<?xml version="1.0" ?>
<!-- =================================================================================== -->
<!-- |    This document was autogenerated by xacro from argonaut_arm_standalone.urdf.xacro | -->
<!-- |    EDITING THIS FILE BY HAND IS NOT RECOMMENDED                                 | -->
<!-- =================================================================================== -->
<robot name="arm_5dof_robot" xmlns:controller="http://playerstage.sourceforge.net/gazebo/xmlschema/#controller" xmlns:interface="http://playerstage.sourceforge.net/gazebo/xmlschema/#interface" xmlns:sensor="http://playerstage.sourceforge.net/gazebo/xmlschema/#sensor" xmlns:xacro="http://playerstage.sourceforge.net/gazebo/xmlschema/#interface">
  <link name="base_link"/>
  <joint name="arm_joint_0" type="revolute">
    <origin rpy="0 0 0" xyz="0 0 0.0"/>
    <axis xyz="0 0 1"/>
    <limit effort="1000" lower="-3.14159265359" upper="3.14159265359" velocity="1.91986217719"/>
    <parent link="base_link"/>
    <child link="arm_link_0"/>
  </joint>
  <link name="arm_link_0">
    <inertial>
      <mass value="1.0"/>
      <origin rpy="0 0 0" xyz="0.0 0.0 0.0"/>
      <inertia ixx="0.005" ixy="0.0" ixz="0.0" iyy="0.005" iyz="0.0" izz="0.005"/>
    </inertial>
    <visual>
      <origin rpy="0 -1.5707963268 0" xyz="0.0 0.0 0.0"/>
      <geometry>
        <box size="0.08 0.08 0.137"/>
      </geometry>
      <material name="DarkGrey">
        <color rgba="0.8 0.8 0.8 1"/>
      </material>
    </visual>
    <collision>
      <origin rpy="0 0 0" xyz="0.0 0.0 0.10525"/>
      <geometry>
        <box size="0.08 0.08 0.137"/>
      </geometry>
    </collision>
  </link>
  <joint name="arm_joint_1" type="revolute">
    <origin rpy="0 0 0" xyz="0.0 0 0.1495"/>
    <axis xyz="0 1 0"/>
    <limit effort="1000" lower="-2.31256125889" upper="2.31256125889" velocity="1.91986217719"/>
    <parent link="arm_link_0"/>
    <child link="arm_link_1"/>
  </joint>
  <link name="arm_link_1">
    <inertial>
      <mass value="1.0"/>
      <origin rpy="0 0 0" xyz="0.0 0.0 0.0"/>
      <inertia ixx="0.005" ixy="0.0" ixz="0.0" iyy="0.005" iyz="0.0" izz="0.005"/>
    </inertial>
    <visual>
      <origin rpy="3.14159265359 -1.5707963268 0" xyz="0.0 0.0184 0.0"/>
      <geometry>
        <box size="0.08 0.08 0.137"/>
      </geometry>
      <material name="DarkGrey">
        <color rgba="0.8 0.8 0.8 1"/>
      </material>
    </visual>
    <collision>
      <origin rpy="0 0 0" xyz="0.0195 0.0634 0.2754"/>
      <geometry>
        <box size="0.08 0.08 0.137"/>
      </geometry>
    </collision>
  </link>
  <joint name="arm_joint_2" type="revolute">
    <origin rpy=" 0 0 0" xyz="0 0.0 0.5508"/>
    <axis xyz="0 1 0"/>
    <limit effort="1000" lower="-2.87979326579" upper="2.87979326579" velocity="1.91986217719"/>
    <parent link="arm_link_1"/>
    <child link="arm_link_2"/>
  </joint>
  <link name="arm_link_2">
    <inertial>
      <mass value="0.1"/>
      <origin rpy="0 0 0" xyz="0.0 0.0 0.0"/>
      <inertia ixx="0.005" ixy="0.0" ixz="0.0" iyy="0.005" iyz="0.0" izz="0.005"/>
    </inertial>
    <visual>
      <origin rpy="0 -1.5707963268 0" xyz="0.0 0.0184 0.0"/>
      <geometry>
        <box size="0.08 0.08 0.137"/>
      </geometry>
      <material name="DarkGrey">
        <color rgba="0.8 0.8 0.8 1"/>
      </material>
    </visual>
    <collision>
      <!--Note fudge factor on y-->
      <origin rpy="0 0 0" xyz="0 -0.0415 0.333"/>
      <geometry>
        <box size="0.086 0.073 0.750"/>
      </geometry>
    </collision>
  </link>
  <joint name="arm_joint_3" type="revolute">
    <origin rpy=" 0 0 0" xyz="0.013 0.0 0.6725"/>
    <axis xyz="0 1 0"/>
    <limit effort="1000" lower="-2.75762021815" upper="2.75762021815" velocity="1.91986217719"/>
    <parent link="arm_link_2"/>
    <child link="arm_link_3"/>
  </joint>
  <link name="arm_link_3">
    <inertial>
      <mass value="0.1"/>
      <origin rpy="0 0 0" xyz="0.0 0.0 0.0"/>
      <inertia ixx="0.005" ixy="0.0" ixz="0.0" iyy="0.005" iyz="0.0" izz="0.005"/>
    </inertial>
    <visual>
      <origin rpy="3.14159265359  -1.5707963268 0" xyz="0.0 0.0184 0.0"/>
      <geometry>
        <box size="0.08 0.08 0.137"/>
      </geometry>
      <material name="DarkGrey">
        <color rgba="0.8 0.8 0.8 1"/>
      </material>
    </visual>
    <collision>
      <origin rpy="0 0 0" xyz="-0.026 0.0589 -0.0665"/>
      <geometry>
        <box size="0.08 0.08 0.137"/>
      </geometry>
    </collision>
  </link>
  <joint name="arm_joint_4" type="revolute">
    <origin rpy=" 0 0 0" xyz="-0.056 0.0589 0.0"/>
    <axis xyz="0 0 1"/>
    <limit effort="1000" lower="-3.14159265359" upper="3.14159265359" velocity="1.91986217719"/>
    <parent link="arm_link_3"/>
    <child link="arm_link_4"/>
  </joint>
  <link name="arm_link_4">
    <inertial>
      <mass value="0.1"/>
      <origin rpy="0 0 0" xyz="0.0 0.0 0.0"/>
      <inertia ixx="0.005" ixy="0.0" ixz="0.0" iyy="0.005" iyz="0.0" izz="0.005"/>
    </inertial>
    <visual>
      <origin rpy="0  1.5707963268 3.14159265359" xyz="0.0 0.0 0.069"/>
      <geometry>
        <box size="0.08 0.08 0.137"/>
      </geometry>
      <material name="DarkGrey">
        <color rgba="0.8 0.8 0.8 1"/>
      </material>
    </visual>
    <collision>
      <origin rpy="0 0 0" xyz="0.019 0.0 0.1825"/>
      <geometry>
        <box size="0.08 0.08 0.137"/>
      </geometry>
    </collision>
  </link>
  <transmission name="arm_joint_0_joint_transmssion">
    <type>transmission_interface/SimpleTransmission</type>
    <joint name="arm_joint_0">
      <hardwareInterface>EffortJointInterface</hardwareInterface>
    </joint>
    <actuator name="arm_joint_0_motor">
      <hardwareInterface>EffortJointInterface</hardwareInterface>
      <mechanicalReduction>1</mechanicalReduction>
    </actuator>
  </transmission>
  <transmission name="arm_joint_1_joint_transmssion">
    <type>transmission_interface/SimpleTransmission</type>
    <joint name="arm_joint_1">
      <hardwareInterface>EffortJointInterface</hardwareInterface>
    </joint>
    <actuator name="arm_joint_1_motor">
      <hardwareInterface>EffortJointInterface</hardwareInterface>
      <mechanicalReduction>1</mechanicalReduction>
    </actuator>
  </transmission>
  <transmission name="arm_joint_2_joint_transmssion">
    <type>transmission_interface/SimpleTransmission</type>
    <joint name="arm_joint_2">
      <hardwareInterface>EffortJointInterface</hardwareInterface>
    </joint>
    <actuator name="arm_joint_2_motor">
      <hardwareInterface>EffortJointInterface</hardwareInterface>
      <mechanicalReduction>1</mechanicalReduction>
    </actuator>
  </transmission>
  <transmission name="arm_joint_3_joint_transmssion">
    <type>transmission_interface/SimpleTransmission</type>
    <joint name="arm_joint_3">
      <hardwareInterface>EffortJointInterface</hardwareInterface>
    </joint>
    <actuator name="arm_joint_3_motor">
      <hardwareInterface>EffortJointInterface</hardwareInterface>
      <mechanicalReduction>1</mechanicalReduction>
    </actuator>
  </transmission>
  <transmission name="arm_joint_4_joint_transmssion">
    <type>transmission_interface/SimpleTransmission</type>
    <joint name="arm_joint_4">
      <hardwareInterface>EffortJointInterface</hardwareInterface>
    </joint>
    <actuator name="arm_joint_4_motor">
      <hardwareInterface>EffortJointInterface</hardwareInterface>
      <mechanicalReduction>1</mechanicalReduction>
    </actuator>
  </transmission>
  <gazebo reference="arm_link_0">
    <material>Gazebo/Grey</material>
  </gazebo>
  <gazebo reference="arm_link_1">
    <material>Gazebo/Grey</material>
  </gazebo>
  <gazebo reference="arm_link_2">
    <material>Gazebo/Grey</material>
  </gazebo>
  <gazebo reference="arm_link_3">
    <material>Gazebo/Grey</material>
  </gazebo>
  <gazebo reference="arm_link_4">
    <material>Gazebo/Grey</material>
  </gazebo>
</robot>

